Workbook

Sheet KPI
R1: Акмолинская
R2: Актюбинская
R3: Алматинская
R4: Атырауская
B5: ДГД | D5: Позиция | F5: Итоговый KPI | R5: ВКО
B6: г.Шымкент | D6: =VLOOKUP(B6,'KPI-20 ДГД'!A:I,9,0) -> 1 | F6: =VLOOKUP(B6,'KPI-20 ДГД'!A:H,8,0) -> 100 | R6: ЗКО
R7: Карагандинская
E8: млн.тг. | R8: Кызылординская
A9: № | B9: Показатель | C9: =MONTH(TODAY())-1&" месяцев "&YEAR(TODAY())&" года" -> 3 месяцев 2026 года | E9: Разница | F9: Исполнение, % | G9: Доля влияния | H9: Баллы | I9: Достигнут да/ нет | R9: Костанайская
C10: KPI | D10: Факт | R10: Мангистауская
A11: 1 | B11: Сумма доначислений | C11: =VLOOKUP(B6,Доначисление!C:H,6,0) -> 533.01022 | D11: =VLOOKUP(B6,Доначисление!C:I,7,0) -> 4102.124 | E11: =D11-C11 -> 3569.1138 | F11: =D11/C11 -> 7.6961452 | G11: 10 | H11: =VLOOKUP(B6,'KPI-20 ДГД'!A:B,2,0) -> 10 | I11: =IF(F11>=100%,"ДА","НЕТ") -> ДА | R11: Павлодарская
A12: 2 | B12: Сумма взысканий | C12: =VLOOKUP(B6,Взыскание!C:H,6,0) -> 206.62806 | D12: =VLOOKUP(B6,Взыскание!C:I,7,0) -> 255.38722 | E12: =D12-C12 -> 48.759161 | F12: =D12/C12 -> 1.2359755 | G12: 40 | H12: =VLOOKUP(B6,'KPI-20 ДГД'!A:C,3,0) -> 40 | I12: =IF(F12>=100%,"ДА","НЕТ") -> ДА | R12: СКО
A13: 3 | B13: Среднее доначисление | C13: =38.32 -> 38.32 | D13: =VLOOKUP(B6,'Среднее доначисление'!C:I,7,0) -> 205.1062 | E13: =D13-C13 -> 166.7862 | F13: =D13/C13 -> 5.3524583 | G13: 10 | H13: =VLOOKUP(B6,'KPI-20 ДГД'!A:D,4,0) -> 10 | I13: =IF(F13>=100%,"ДА","НЕТ") -> ДА | R13: Туркестанская
A14: 4 | B14: Коэффициент занятости | C14: 0.5 | D14: =VLOOKUP(B6,Занятость!C:F,4,0) -> 0.51282051 | E14: =D14-C14 -> 0.012820513 | F14: =D14/C14 -> 1.025641 | G14: 15 | H14: =VLOOKUP(B6,'KPI-20 ДГД'!A:E,5,0) -> 15 | I14: =IF(F14>=100%,"ДА","НЕТ") -> ДА | R14: г.Шымкент
R15: г.Алматы
A16: 5 | B16: Доля проверок > 6 мес, % | C16: =MONTH(TODAY())-1&" месяцев "&YEAR(TODAY())&" года" -> 3 месяцев 2026 года | E16: Разница | F16: Удельный вес, % | G16: Доля влияния | H16: Баллы | I16: Достигнут да/ нет | R16: г.Астана
C17: Всего проверок | D17: > 6 мес. | R17: Область Жетісу
C18: =VLOOKUP(B6,Проводимые!C:D,2,0) -> 22 | D18: =VLOOKUP(B6,Проводимые!C:E,3,0) -> 2 | E18: =C18-D18 -> 20 | F18: =D18/C18 -> 0.090909091 | G18: 10 | H18: =VLOOKUP(B6,'KPI-20 ДГД'!A:F,6,0) -> 10 | I18: =IF(F18<20%,"ДА","НЕТ") -> ДА | R18: Область Абай
E19: млн.тг. | R19: Область Ұлытау
A20: 6 | B20: Удельный вес отмененных сумм доначислений | C20: =MONTH(TODAY())-1&" месяцев "&YEAR(TODAY())&" года" -> 3 месяцев 2026 года | E20: Разница | F20: Удельный вес, % | G20: Доля влияния | H20: Баллы | I20: Достигнут да/ нет | R20: Жамбылская
C21: Всего доначислено | D21: Отмененная сумма | R21: КГД
C22: =VLOOKUP(B6,Отмененные!C:D,2,0) -> 4102.124 | D22: =VLOOKUP(B6,Отмененные!C:G,5,0) -> 0 | E22: =D22-C22 -> -4102.124 | F22: =IFERROR(D22/C22,IF(KPI!D22>=1,KPI!D22,0)) -> 0 | G22: 15 | H22: =VLOOKUP(B6,'KPI-20 ДГД'!A:G,7,0) -> 15 | I22: =IF(F22<=1%,"ДА","НЕТ") -> ДА

Sheet Для УСР
B1: KPI по УНА за 3 месяца 2026 года
B3: ДГД | C3: Наименование KPI | E3: KPI | F3: Факт | G3: Достигнут | H3: Балл | I3: KPI | J3: Факт, %
B5: Акмолинская | C5: 1 | D5: Сумма доначислений | E5: =VLOOKUP(B5,Доначисление!C:H,6,0) -> 361.20109 | F5: =VLOOKUP(B5,Доначисление!C:I,7,0) -> 4.635403 | G5: =IF(H5>9,"да","нет") -> нет | H5: =VLOOKUP(B5,Доначисление!C:O,13,0) -> 0 | I5: 1 | J5: =F5*100/E5 -> 1.2833303
B6: Акмолинская | C6: 2 | D6: Сумма взысканий | E6: =VLOOKUP(B6,Взыскание!C:H,6,0) -> 140.02411 | F6: =VLOOKUP(B6,Взыскание!C:I,7,0) -> 961.45756 | G6: =IF(H6>=40,"да","нет") -> да | H6: =VLOOKUP(B6,Взыскание!C:L,10,0) -> 40 | I6: 1 | J6: =F6*100/E6 -> 686.63716
B7: Акмолинская | C7: 3 | D7: Среднее доначисление | E7: =VLOOKUP(B7,'Среднее доначисление'!C:J,8,0) -> 38.32 | F7: =VLOOKUP(B7,'Среднее доначисление'!C:I,7,0) -> 0.38628358 | G7: =IF(H7>=10,"да","нет") -> нет | H7: =VLOOKUP(B7,'Среднее доначисление'!C:M,11,0) -> 0 | I7: 1 | J7: =F7*100/E7 -> 1.0080469
B8: Акмолинская | C8: 4 | D8: Коэффициент занятости | E8: 0.5 | F8: =VLOOKUP(B8,Занятость!C:F,4,0) -> 0.36363636 | G8: =IF(H8>=10,"да","нет") -> нет | H8: =VLOOKUP(B8,Занятость!C:G,5,0) -> 0 | I8: =E8 -> 0.5 | J8: =F8 -> 0.36363636
B9: Акмолинская | C9: 5 | D9: Доля проверок > 6 мес, % | E9: 0.2 | F9: =VLOOKUP(B9,Проводимые!C:F,4,0)*100 -> 0 | G9: =IF(H9>=10,"да","нет") -> да | H9: =VLOOKUP(B9,Проводимые!C:G,5,0) -> 10 | I9: 0.2 | J9: =F9 -> 0
B10: Акмолинская | C10: 6 | D10: Удельный вес отмененных сумм доначислений | E10: 0.01 | F10: =VLOOKUP(B10,Отмененные!C:I,7,0) -> 344.64317 | G10: =IF(H10>=10,"да","нет") -> нет | H10: =VLOOKUP(B10,Отмененные!C:J,8,0) -> 0 | I10: 0.01 | J10: =F10 -> 344.64317
B11: Актюбинская | C11: 1 | D11: Сумма доначислений | E11: =VLOOKUP(B11,Доначисление!C:H,6,0) -> 524.72171 | F11: =VLOOKUP(B11,Доначисление!C:I,7,0) -> 2608.9058 | G11: =IF(H11>9,"да","нет") -> да | H11: =VLOOKUP(B11,Доначисление!C:O,13,0) -> 10 | I11: 1 | J11: =F11*100/E11 -> 497.19799
B12: Актюбинская | C12: 2 | D12: Сумма взысканий | E12: =VLOOKUP(B12,Взыскание!C:H,6,0) -> 203.41491 | F12: =VLOOKUP(B12,Взыскание!C:I,7,0) -> 1301.693 | G12: =IF(H12>=40,"да","нет") -> да | H12: =VLOOKUP(B12,Взыскание!C:L,10,0) -> 40 | I12: 1 | J12: =F12*100/E12 -> 639.92016
B13: Актюбинская | C13: 3 | D13: Среднее доначисление | E13: =VLOOKUP(B13,'Среднее доначисление'!C:J,8,0) -> 38.32 | F13: =VLOOKUP(B13,'Среднее доначисление'!C:I,7,0) -> 118.58663 | G13: =IF(H13>=10,"да","нет") -> да | H13: =VLOOKUP(B13,'Среднее доначисление'!C:M,11,0) -> 10 | I13: 1 | J13: =F13*100/E13 -> 309.46406
B14: Актюбинская | C14: 4 | D14: Коэффициент занятости | E14: 0.5 | F14: =VLOOKUP(B14,Занятость!C:F,4,0) -> 0.40740741 | G14: =IF(H14>=10,"да","нет") -> нет | H14: =VLOOKUP(B14,Занятость!C:G,5,0) -> 5 | I14: =E14 -> 0.5 | J14: =F14 -> 0.40740741
B15: Актюбинская | C15: 5 | D15: Доля проверок > 6 мес, % | E15: 0.2 | F15: =VLOOKUP(B15,Проводимые!C:F,4,0)*100 -> 10.526316 | G15: =IF(H15>=10,"да","нет") -> да | H15: =VLOOKUP(B15,Проводимые!C:G,5,0) -> 10 | I15: 0.2 | J15: =F15 -> 10.526316
B16: Актюбинская | C16: 6 | D16: Удельный вес отмененных сумм доначислений | E16: 0.01 | F16: =VLOOKUP(B16,Отмененные!C:I,7,0) -> 0 | G16: =IF(H16>=10,"да","нет") -> да | H16: =VLOOKUP(B16,Отмененные!C:J,8,0) -> 15 | I16: 0.01 | J16: =F16 -> 0
B17: Алматинская | C17: 1 | D17: Сумма доначислений | E17: =VLOOKUP(B17,Доначисление!C:H,6,0) -> 686.48855 | F17: =VLOOKUP(B17,Доначисление!C:I,7,0) -> 1511.0814 | G17: =IF(H17>9,"да","нет") -> да | H17: =VLOOKUP(B17,Доначисление!C:O,13,0) -> 10 | I17: 1 | J17: =F17*100/E17 -> 220.11749
B18: Алматинская | C18: 2 | D18: Сумма взысканий | E18: =VLOOKUP(B18,Взыскание!C:H,6,0) -> 266.12585 | F18: =VLOOKUP(B18,Взыскание!C:I,7,0) -> 333.55386 | G18: =IF(H18>=40,"да","нет") -> да | H18: =VLOOKUP(B18,Взыскание!C:L,10,0) -> 40 | I18: 1 | J18: =F18*100/E18 -> 125.33689
B19: Алматинская | C19: 3 | D19: Среднее доначисление | E19: =VLOOKUP(B19,'Среднее доначисление'!C:J,8,0) -> 38.32 | F19: =VLOOKUP(B19,'Среднее доначисление'!C:I,7,0) -> 215.86877 | G19: =IF(H19>=10,"да","нет") -> да | H19: =VLOOKUP(B19,'Среднее доначисление'!C:M,11,0) -> 10 | I19: 1 | J19: =F19*100/E19 -> 563.33186
B20: Алматинская | C20: 4 | D20: Коэффициент занятости | E20: 0.5 | F20: =VLOOKUP(B20,Занятость!C:F,4,0) -> 0.15555556 | G20: =IF(H20>=10,"да","нет") -> нет | H20: =VLOOKUP(B20,Занятость!C:G,5,0) -> 0 | I20: =E20 -> 0.5 | J20: =F20 -> 0.15555556
B21: Алматинская | C21: 5 | D21: Доля проверок > 6 мес, % | E21: 0.2 | F21: =VLOOKUP(B21,Проводимые!C:F,4,0)*100 -> 0 | G21: =IF(H21>=10,"да","нет") -> да | H21: =VLOOKUP(B21,Проводимые!C:G,5,0) -> 10 | I21: 0.2 | J21: =F21 -> 0
B22: Алматинская | C22: 6 | D22: Удельный вес отмененных сумм доначислений | E22: 0.01 | F22: =VLOOKUP(B22,Отмененные!C:I,7,0) -> 0.093416544 | G22: =IF(H22>=10,"да","нет") -> да | H22: =VLOOKUP(B22,Отмененные!C:J,8,0) -> 15 | I22: 0.01 | J22: =F22 -> 0.093416544
B23: Атырауская | C23: 1 | D23: Сумма доначислений | E23: =VLOOKUP(B23,Доначисление!C:H,6,0) -> 1012.4767 | F23: =VLOOKUP(B23,Доначисление!C:I,7,0) -> 83.797924 | G23: =IF(H23>9,"да","нет") -> нет | H23: =VLOOKUP(B23,Доначисление!C:O,13,0) -> 0 | I23: 1 | J23: =F23*100/E23 -> 8.2765289
B24: Атырауская | C24: 2 | D24: Сумма взысканий | E24: =VLOOKUP(B24,Взыскание!C:H,6,0) -> 392.49921 | F24: =VLOOKUP(B24,Взыскание!C:I,7,0) -> 1174.8994 | G24: =IF(H24>=40,"да","нет") -> да | H24: =VLOOKUP(B24,Взыскание!C:L,10,0) -> 40 | I24: 1 | J24: =F24*100/E24 -> 299.33804
B25: Атырауская | C25: 3 | D25: Среднее доначисление | E25: =VLOOKUP(B25,'Среднее доначисление'!C:J,8,0) -> 38.32 | F25: =VLOOKUP(B25,'Среднее доначисление'!C:I,7,0) -> 4.6554402 | G25: =IF(H25>=10,"да","нет") -> нет | H25: =VLOOKUP(B25,'Среднее доначисление'!C:M,11,0) -> 0 | I25: 1 | J25: =F25*100/E25 -> 12.148852
B26: Атырауская | C26: 4 | D26: Коэффициент занятости | E26: 0.5 | F26: =VLOOKUP(B26,Занятость!C:F,4,0) -> 0.75 | G26: =IF(H26>=10,"да","нет") -> да | H26: =VLOOKUP(B26,Занятость!C:G,5,0) -> 15 | I26: =E26 -> 0.5 | J26: =F26 -> 0.75
B27: Атырауская | C27: 5 | D27: Доля проверок > 6 мес, % | E27: 0.2 | F27: =VLOOKUP(B27,Проводимые!C:F,4,0)*100 -> 4.7619048 | G27: =IF(H27>=10,"да","нет") -> да | H27: =VLOOKUP(B27,Проводимые!C:G,5,0) -> 10 | I27: 0.2 | J27: =F27 -> 4.7619048
B28: Атырауская | C28: 6 | D28: Удельный вес отмененных сумм доначислений | E28: 0.01 | F28: =VLOOKUP(B28,Отмененные!C:I,7,0) -> 5.7993084 | G28: =IF(H28>=10,"да","нет") -> нет | H28: =VLOOKUP(B28,Отмененные!C:J,8,0) -> 0 | I28: 0.01 | J28: =F28 -> 5.7993084
B29: ВКО | C29: 1 | D29: Сумма доначислений | E29: =VLOOKUP(B29,Доначисление!C:H,6,0) -> 496.36951 | F29: =VLOOKUP(B29,Доначисление!C:I,7,0) -> 704.02056 | G29: =IF(H29>9,"да","нет") -> да | H29: =VLOOKUP(B29,Доначисление!C:O,13,0) -> 10 | I29: 1 | J29: =F29*100/E29 -> 141.83397
B30: ВКО | C30: 2 | D30: Сумма взысканий | E30: =VLOOKUP(B30,Взыскание!C:H,6,0) -> 192.42383 | F30: =VLOOKUP(B30,Взыскание!C:I,7,0) -> 592.34982 | G30: =IF(H30>=40,"да","нет") -> да | H30: =VLOOKUP(B30,Взыскание!C:L,10,0) -> 40 | I30: 1 | J30: =F30*100/E30 -> 307.836
B31: ВКО | C31: 3 | D31: Среднее доначисление | E31: =VLOOKUP(B31,'Среднее доначисление'!C:J,8,0) -> 38.32 | F31: =VLOOKUP(B31,'Среднее доначисление'!C:I,7,0) -> 176.00514 | G31: =IF(H31>=10,"да","нет") -> да | H31: =VLOOKUP(B31,'Среднее доначисление'!C:M,11,0) -> 10 | I31: 1 | J31: =F31*100/E31 -> 459.3036
B32: ВКО | C32: 4 | D32: Коэффициент занятости | E32: 0.5 | F32: =VLOOKUP(B32,Занятость!C:F,4,0) -> 0.066666667 | G32: =IF(H32>=10,"да","нет") -> нет | H32: =VLOOKUP(B32,Занятость!C:G,5,0) -> 0 | I32: =E32 -> 0.5 | J32: =F32 -> 0.066666667
B33: ВКО | C33: 5 | D33: Доля проверок > 6 мес, % | E33: 0.2 | F33: =VLOOKUP(B33,Проводимые!C:F,4,0)*100 -> 12.5 | G33: =IF(H33>=10,"да","нет") -> да | H33: =VLOOKUP(B33,Проводимые!C:G,5,0) -> 10 | I33: 0.2 | J33: =F33 -> 12.5
B34: ВКО | C34: 6 | D34: Удельный вес отмененных сумм доначислений | E34: 0.01 | F34: =VLOOKUP(B34,Отмененные!C:I,7,0) -> 0.67415645 | G34: =IF(H34>=10,"да","нет") -> да | H34: =VLOOKUP(B34,Отмененные!C:J,8,0) -> 15 | I34: 0.01 | J34: =F34 -> 0.67415645
B35: Жамбылская | C35: 1 | D35: Сумма доначислений | E35: =VLOOKUP(B35,Доначисление!C:H,6,0) -> 240.2935 | F35: =VLOOKUP(B35,Доначисление!C:I,7,0) -> 39.948959 | G35: =IF(H35>9,"да","нет") -> нет | H35: =VLOOKUP(B35,Доначисление!C:O,13,0) -> 0 | I35: 1 | J35: =F35*100/E35 -> 16.625068
B36: Жамбылская | C36: 2 | D36: Сумма взысканий | E36: =VLOOKUP(B36,Взыскание!C:H,6,0) -> 93.152772 | F36: =VLOOKUP(B36,Взыскание!C:I,7,0) -> 854.66994 | G36: =IF(H36>=40,"да","нет") -> да | H36: =VLOOKUP(B36,Взыскание!C:L,10,0) -> 40 | I36: 1 | J36: =F36*100/E36 -> 917.49276
B37: Жамбылская | C37: 3 | D37: Среднее доначисление | E37: =VLOOKUP(B37,'Среднее доначисление'!C:J,8,0) -> 38.32 | F37: =VLOOKUP(B37,'Среднее доначисление'!C:I,7,0) -> 9.9872397 | G37: =IF(H37>=10,"да","нет") -> нет | H37: =VLOOKUP(B37,'Среднее доначисление'!C:M,11,0) -> 0 | I37: 1 | J37: =F37*100/E37 -> 26.062734
B38: Жамбылская | C38: 4 | D38: Коэффициент занятости | E38: 0.5 | F38: =VLOOKUP(B38,Занятость!C:F,4,0) -> 0.088888889 | G38: =IF(H38>=10,"да","нет") -> нет | H38: =VLOOKUP(B38,Занятость!C:G,5,0) -> 0 | I38: =E38 -> 0.5 | J38: =F38 -> 0.088888889
B39: Жамбылская | C39: 5 | D39: Доля проверок > 6 мес, % | E39: 0.2 | F39: =VLOOKUP(B39,Проводимые!C:F,4,0)*100 -> 0 | G39: =IF(H39>=10,"да","нет") -> да | H39: =VLOOKUP(B39,Проводимые!C:G,5,0) -> 10 | I39: 0.2 | J39: =F39 -> 0
B40: Жамбылская | C40: 6 | D40: Удельный вес отмененных сумм доначислений | E40: 0.01 | F40: =VLOOKUP(B40,Отмененные!C:I,7,0) -> 0 | G40: =IF(H40>=10,"да","нет") -> да | H40: =VLOOKUP(B40,Отмененные!C:J,8,0) -> 15 | I40: 0.01 | J40: =F40 -> 0
B41: ЗКО | C41: 1 | D41: Сумма доначислений | E41: =VLOOKUP(B41,Доначисление!C:H,6,0) -> 335.93498 | F41: =VLOOKUP(B41,Доначисление!C:I,7,0) -> 12.336714 | G41: =IF(H41>9,"да","нет") -> нет | H41: =VLOOKUP(B41,Доначисление!C:O,13,0) -> 0 | I41: 1 | J41: =F41*100/E41 -> 3.6723515
B42: ЗКО | C42: 2 | D42: Сумма взысканий | E42: =VLOOKUP(B42,Взыскание!C:H,6,0) -> 130.22939 | F42: =VLOOKUP(B42,Взыскание!C:I,7,0) -> 402.34887 | G42: =IF(H42>=40,"да","нет") -> да | H42: =VLOOKUP(B42,Взыскание!C:L,10,0) -> 40 | I42: 1 | J42: =F42*100/E42 -> 308.95398
...

Sheet KPI-20 ДГД
A1: Баллы на 01.04.2026
A3: ДГД | B3: Доначисление | C3: Взыскание | D3: Доначисление на 1 проверку | E3: Коэффициент занятости | F3: Доля проверок > 6 мес, % | G3: Удельный вес отмененных сумм доначислений | H3: Баллы | I3: Позиция
A4: Акмолинская | B4: =SUMIF(Доначисление!C:C,'KPI-20 ДГД'!A4,Доначисление!O:O) -> 0 | C4: =SUMIF(Взыскание!C:C,'KPI-20 ДГД'!A4,Взыскание!L:L) -> 40 | D4: =SUMIF('Среднее доначисление'!C:C,'KPI-20 ДГД'!A4,'Среднее доначисление'!M:M) -> 0 | E4: =SUMIF(Занятость!C:C,'KPI-20 ДГД'!A4,Занятость!G:G) -> 0 | F4: =SUMIF(Проводимые!C:C,'KPI-20 ДГД'!A4,Проводимые!G:G) -> 10 | G4: =SUMIF(Отмененные!C:C,'KPI-20 ДГД'!A4,Отмененные!J:J) -> 0 | H4: =SUM(B4:G4) -> 50 | I4: =RANK(H4,$H$4:$H$23,0) -> 19
A5: Актюбинская | B5: =SUMIF(Доначисление!C:C,'KPI-20 ДГД'!A5,Доначисление!O:O) -> 10 | C5: =SUMIF(Взыскание!C:C,'KPI-20 ДГД'!A5,Взыскание!L:L) -> 40 | D5: =SUMIF('Среднее доначисление'!C:C,'KPI-20 ДГД'!A5,'Среднее доначисление'!M:M) -> 10 | E5: =SUMIF(Занятость!C:C,'KPI-20 ДГД'!A5,Занятость!G:G) -> 5 | F5: =SUMIF(Проводимые!C:C,'KPI-20 ДГД'!A5,Проводимые!G:G) -> 10 | G5: =SUMIF(Отмененные!C:C,'KPI-20 ДГД'!A5,Отмененные!J:J) -> 15 | H5: =SUM(B5:G5) -> 90 | I5: =RANK(H5,$H$4:$H$23,0) -> 4
A6: Алматинская | B6: =SUMIF(Доначисление!C:C,'KPI-20 ДГД'!A6,Доначисление!O:O) -> 10 | C6: =SUMIF(Взыскание!C:C,'KPI-20 ДГД'!A6,Взыскание!L:L) -> 40 | D6: =SUMIF('Среднее доначисление'!C:C,'KPI-20 ДГД'!A6,'Среднее доначисление'!M:M) -> 10 | E6: =SUMIF(Занятость!C:C,'KPI-20 ДГД'!A6,Занятость!G:G) -> 0 | F6: =SUMIF(Проводимые!C:C,'KPI-20 ДГД'!A6,Проводимые!G:G) -> 10 | G6: =SUMIF(Отмененные!C:C,'KPI-20 ДГД'!A6,Отмененные!J:J) -> 15 | H6: =SUM(B6:G6) -> 85 | I6: =RANK(H6,$H$4:$H$23,0) -> 7
A7: Атырауская | B7: =SUMIF(Доначисление!C:C,'KPI-20 ДГД'!A7,Доначисление!O:O) -> 0 | C7: =SUMIF(Взыскание!C:C,'KPI-20 ДГД'!A7,Взыскание!L:L) -> 40 | D7: =SUMIF('Среднее доначисление'!C:C,'KPI-20 ДГД'!A7,'Среднее доначисление'!M:M) -> 0 | E7: =SUMIF(Занятость!C:C,'KPI-20 ДГД'!A7,Занятость!G:G) -> 15 | F7: =SUMIF(Проводимые!C:C,'KPI-20 ДГД'!A7,Проводимые!G:G) -> 10 | G7: =SUMIF(Отмененные!C:C,'KPI-20 ДГД'!A7,Отмененные!J:J) -> 0 | H7: =SUM(B7:G7) -> 65 | I7: =RANK(H7,$H$4:$H$23,0) -> 14
A8: ВКО | B8: =SUMIF(Доначисление!C:C,'KPI-20 ДГД'!A8,Доначисление!O:O) -> 10 | C8: =SUMIF(Взыскание!C:C,'KPI-20 ДГД'!A8,Взыскание!L:L) -> 40 | D8: =SUMIF('Среднее доначисление'!C:C,'KPI-20 ДГД'!A8,'Среднее доначисление'!M:M) -> 10 | E8: =SUMIF(Занятость!C:C,'KPI-20 ДГД'!A8,Занятость!G:G) -> 0 | F8: =SUMIF(Проводимые!C:C,'KPI-20 ДГД'!A8,Проводимые!G:G) -> 10 | G8: =SUMIF(Отмененные!C:C,'KPI-20 ДГД'!A8,Отмененные!J:J) -> 15 | H8: =SUM(B8:G8) -> 85 | I8: =RANK(H8,$H$4:$H$23,0) -> 7
A9: Жамбылская | B9: =SUMIF(Доначисление!C:C,'KPI-20 ДГД'!A9,Доначисление!O:O) -> 0 | C9: =SUMIF(Взыскание!C:C,'KPI-20 ДГД'!A9,Взыскание!L:L) -> 40 | D9: =SUMIF('Среднее доначисление'!C:C,'KPI-20 ДГД'!A9,'Среднее доначисление'!M:M) -> 0 | E9: =SUMIF(Занятость!C:C,'KPI-20 ДГД'!A9,Занятость!G:G) -> 0 | F9: =SUMIF(Проводимые!C:C,'KPI-20 ДГД'!A9,Проводимые!G:G) -> 10 | G9: =SUMIF(Отмененные!C:C,'KPI-20 ДГД'!A9,Отмененные!J:J) -> 15 | H9: =SUM(B9:G9) -> 65 | I9: =RANK(H9,$H$4:$H$23,0) -> 14
A10: ЗКО | B10: =SUMIF(Доначисление!C:C,'KPI-20 ДГД'!A10,Доначисление!O:O) -> 0 | C10: =SUMIF(Взыскание!C:C,'KPI-20 ДГД'!A10,Взыскание!L:L) -> 40 | D10: =SUMIF('Среднее доначисление'!C:C,'KPI-20 ДГД'!A10,'Среднее доначисление'!M:M) -> 0 | E10: =SUMIF(Занятость!C:C,'KPI-20 ДГД'!A10,Занятость!G:G) -> 15 | F10: =SUMIF(Проводимые!C:C,'KPI-20 ДГД'!A10,Проводимые!G:G) -> 10 | G10: =SUMIF(Отмененные!C:C,'KPI-20 ДГД'!A10,Отмененные!J:J) -> 0 | H10: =SUM(B10:G10) -> 65 | I10: =RANK(H10,$H$4:$H$23,0) -> 14
A11: Карагандинская | B11: =SUMIF(Доначисление!C:C,'KPI-20 ДГД'!A11,Доначисление!O:O) -> 10 | C11: =SUMIF(Взыскание!C:C,'KPI-20 ДГД'!A11,Взыскание!L:L) -> 40 | D11: =SUMIF('Среднее доначисление'!C:C,'KPI-20 ДГД'!A11,'Среднее доначисление'!M:M) -> 10 | E11: =SUMIF(Занятость!C:C,'KPI-20 ДГД'!A11,Занятость!G:G) -> 15 | F11: =SUMIF(Проводимые!C:C,'KPI-20 ДГД'!A11,Проводимые!G:G) -> 10 | G11: =SUMIF(Отмененные!C:C,'KPI-20 ДГД'!A11,Отмененные!J:J) -> 0 | H11: =SUM(B11:G11) -> 85 | I11: =RANK(H11,$H$4:$H$23,0) -> 7
A12: Кызылординская | B12: =SUMIF(Доначисление!C:C,'KPI-20 ДГД'!A12,Доначисление!O:O) -> 10 | C12: =SUMIF(Взыскание!C:C,'KPI-20 ДГД'!A12,Взыскание!L:L) -> 40 | D12: =SUMIF('Среднее доначисление'!C:C,'KPI-20 ДГД'!A12,'Среднее доначисление'!M:M) -> 0 | E12: =SUMIF(Занятость!C:C,'KPI-20 ДГД'!A12,Занятость!G:G) -> 0 | F12: =SUMIF(Проводимые!C:C,'KPI-20 ДГД'!A12,Проводимые!G:G) -> 10 | G12: =SUMIF(Отмененные!C:C,'KPI-20 ДГД'!A12,Отмененные!J:J) -> 15 | H12: =SUM(B12:G12) -> 75 | I12: =RANK(H12,$H$4:$H$23,0) -> 11
A13: Костанайская | B13: =SUMIF(Доначисление!C:C,'KPI-20 ДГД'!A13,Доначисление!O:O) -> 10 | C13: =SUMIF(Взыскание!C:C,'KPI-20 ДГД'!A13,Взыскание!L:L) -> 20 | D13: =SUMIF('Среднее доначисление'!C:C,'KPI-20 ДГД'!A13,'Среднее доначисление'!M:M) -> 10 | E13: =SUMIF(Занятость!C:C,'KPI-20 ДГД'!A13,Занятость!G:G) -> 0 | F13: =SUMIF(Проводимые!C:C,'KPI-20 ДГД'!A13,Проводимые!G:G) -> 10 | G13: =SUMIF(Отмененные!C:C,'KPI-20 ДГД'!A13,Отмененные!J:J) -> 15 | H13: =SUM(B13:G13) -> 65 | I13: =RANK(H13,$H$4:$H$23,0) -> 14
A14: Мангистауская | B14: =SUMIF(Доначисление!C:C,'KPI-20 ДГД'!A14,Доначисление!O:O) -> 10 | C14: =SUMIF(Взыскание!C:C,'KPI-20 ДГД'!A14,Взыскание!L:L) -> 10 | D14: =SUMIF('Среднее доначисление'!C:C,'KPI-20 ДГД'!A14,'Среднее доначисление'!M:M) -> 10 | E14: =SUMIF(Занятость!C:C,'KPI-20 ДГД'!A14,Занятость!G:G) -> 5 | F14: =SUMIF(Проводимые!C:C,'KPI-20 ДГД'!A14,Проводимые!G:G) -> 0 | G14: =SUMIF(Отмененные!C:C,'KPI-20 ДГД'!A14,Отмененные!J:J) -> 15 | H14: =SUM(B14:G14) -> 50 | I14: =RANK(H14,$H$4:$H$23,0) -> 19
A15: Павлодарская | B15: =SUMIF(Доначисление!C:C,'KPI-20 ДГД'!A15,Доначисление!O:O) -> 10 | C15: =SUMIF(Взыскание!C:C,'KPI-20 ДГД'!A15,Взыскание!L:L) -> 40 | D15: =SUMIF('Среднее доначисление'!C:C,'KPI-20 ДГД'!A15,'Среднее доначисление'!M:M) -> 10 | E15: =SUMIF(Занятость!C:C,'KPI-20 ДГД'!A15,Занятость!G:G) -> 15 | F15: =SUMIF(Проводимые!C:C,'KPI-20 ДГД'!A15,Проводимые!G:G) -> 10 | G15: =SUMIF(Отмененные!C:C,'KPI-20 ДГД'!A15,Отмененные!J:J) -> 15 | H15: =SUM(B15:G15) -> 100 | I15: =RANK(H15,$H$4:$H$23,0) -> 1
... A23: Область Ұлытау | B23: =SUMIF(Доначисление!C:C,'KPI-20 ДГД'!A23,Доначисление!O:O) -> 10 | C23: =SUMIF(Взыскание!C:C,'KPI-20 ДГД'!A23,Взыскание!L:L) -> 40 | D23: =SUMIF('Среднее доначисление'!C:C,'KPI-20 ДГД'!A23,'Среднее доначисление'!M:M) -> 10 | E23: =SUMIF(Занятость!C:C,'KPI-20 ДГД'!A23,Занятость!G:G) -> 0 | F23: =SUMIF(Проводимые!C:C,'KPI-20 ДГД'!A23,Проводимые!G:G) -> 10 | G23: =SUMIF(Отмененные!C:C,'KPI-20 ДГД'!A23,Отмененные!J:J) -> 0 | H23: =SUM(B23:G23) -> 70 | I23: =RANK(H23,$H$4:$H$23,0) -> 12
A24: КГД | B24: =SUMIF(Доначисление!C:C,'KPI-20 ДГД'!A24,Доначисление!O:O) -> 10 | C24: =SUMIF(Взыскание!C:C,'KPI-20 ДГД'!A24,Взыскание!L:L) -> 40 | D24: =SUMIF('Среднее доначисление'!C:C,'KPI-20 ДГД'!A24,'Среднее доначисление'!M:M) -> 10 | E24: =SUMIF(Занятость!C:C,'KPI-20 ДГД'!A24,Занятость!G:G) -> 0 | F24: =SUMIF(Проводимые!C:C,'KPI-20 ДГД'!A24,Проводимые!G:G) -> 10 | G24: =SUMIF(Отмененные!C:C,'KPI-20 ДГД'!A24,Отмененные!J:J) -> 15 | H24: =SUM(B24:G24) -> 85 | I24: -

Sheet KPI-печать
A1: Баллы на 01.04.2026
A3: ДГД | B3: Доначисление | C3: Взыскание | D3: Доначисление на 1 проверку | E3: Коэффициент занятости | F3: Доля проверок > 6 мес, % | G3: Удельный вес отмененных сумм доначислений | H3: Баллы | I3: Позиция
A4: Павлодарская | B4: 10 | C4: 40 | D4: 10 | E4: 15 | F4: 10 | G4: 15 | H4: 100 | I4: 1
A5: г.Шымкент | B5: 10 | C5: 40 | D5: 10 | E5: 15 | F5: 10 | G5: 15 | H5: 100 | I5: 1
A6: Область Жетісу | B6: 10 | C6: 40 | D6: 10 | E6: 15 | F6: 10 | G6: 15 | H6: 100 | I6: 1
A7: Актюбинская | B7: 10 | C7: 40 | D7: 10 | E7: 5 | F7: 10 | G7: 15 | H7: 90 | I7: 4
A8: г.Алматы | B8: 10 | C8: 40 | D8: 10 | E8: 5 | F8: 10 | G8: 15 | H8: 90 | I8: 4
A9: Область Абай | B9: 10 | C9: 40 | D9: 0 | E9: 15 | F9: 10 | G9: 15 | H9: 90 | I9: 4
A10: Алматинская | B10: 10 | C10: 40 | D10: 10 | E10: 0 | F10: 10 | G10: 15 | H10: 85 | I10: 7
A11: ВКО | B11: 10 | C11: 40 | D11: 10 | E11: 0 | F11: 10 | G11: 15 | H11: 85 | I11: 7
A12: Карагандинская | B12: 10 | C12: 40 | D12: 10 | E12: 15 | F12: 10 | G12: 0 | H12: 85 | I12: 7
A13: СКО | B13: 10 | C13: 40 | D13: 10 | E13: 0 | F13: 10 | G13: 15 | H13: 85 | I13: 7
A14: Кызылординская | B14: 10 | C14: 40 | D14: 0 | E14: 0 | F14: 10 | G14: 15 | H14: 75 | I14: 11
A15: г.Астана | B15: 0 | C15: 20 | D15: 10 | E15: 15 | F15: 10 | G15: 15 | H15: 70 | I15: 12
... A23: Мангистауская | B23: 10 | C23: 10 | D23: 10 | E23: 5 | F23: 0 | G23: 15 | H23: 50 | I23: 19
A24: КГД | B24: 10 | C24: 40 | D24: 10 | E24: 0 | F24: 10 | G24: 15 | H24: 85 | I24: -

Sheet Доначисление
B2: Динамика доначисленных сумм на 01.04.2026
I3: млн.тг.
B4: № | C4: ДГД | D4: Доля в % по 4 КБК | E4: Доначислено на 01.01.2026 | F4: Темп роста +120% | G4: KPI на 01.01.2027 | H4: KPI на 01.04.2026 | I4: Факт на 01.04.2026 | J4: Данные КГД на 01.04.2026 | K4: Данные ДГД на 01.04.2026 | L4: Отклонение | M4: Исполнение KPI | O4: Баллы | P4: Доначислено на 01.03.2026 | Q4: Темп роста | R4: Откл | S4: Доначислено на 01.04.2025 | T4: Темп роста
M5: в сумме | N5: в %
A6: 58xx | B6: =RANK(N6,$N$6:$N$25,0) -> 14 | C6: Туркестанская | D6: 2.614949 | E6: 7752.9492 | F6: =E6*120% -> 9303.5391 | G6: =D6%*$F$26 -> 4595.9261 | H6: 459.59261 | I6: =MIN(J6:K6) -> 492.47053 | J6: =SUMIFS('Завершенные ИНИС и ИСНА'!U:U,'Завершенные ИНИС и ИСНА'!T:T,"УНА",'Завершенные ИНИС и ИСНА'!C:C,Доначисление!A6)/1000000 -> 492.47053 | K6: =SUMIFS('Завершенные данные ДГД'!AH:AH,'Завершенные данные ДГД'!AS:AS,"УНА",'Завершенные данные ДГД'!L:L,">01.01.2026",'Завершенные данные ДГД'!C:C,Доначисление!A6)/1000000 -> 492.47053 | L6: =K6-J6 -> -4.6999997e-07 | M6: =I6-H6 -> 32.877921 | N6: =I6/H6 -> 1.0715371 | O6: =IF(N6<90%,0,IF(N6<=99.999999%,5,IF(N6>=100%,10,""))) -> 10 | P6: 78.333259 | Q6: =I6/P6*100 -> 628.68638 | R6: =I6-P6 -> 414.13727 | S6: 1786.2055 | T6: =I6/S6*100 -> 27.570766
A7: 70xx | B7: =RANK(N7,$N$6:$N$25,0) -> 1 | C7: область Жетісу | D7: 0.95788406 | E7: 3866.5806 | F7: =E7*120% -> 4639.8967 | G7: =D7%*$F$26 -> 1683.5374 | H7: 168.35374 | I7: =MIN(J7:K7) -> 1859.4109 | J7: =SUMIFS('Завершенные ИНИС и ИСНА'!U:U,'Завершенные ИНИС и ИСНА'!T:T,"УНА",'Завершенные ИНИС и ИСНА'!C:C,Доначисление!A7)/1000000 -> 1859.6706 | K7: =SUMIFS('Завершенные данные ДГД'!AH:AH,'Завершенные данные ДГД'!AS:AS,"УНА",'Завершенные данные ДГД'!L:L,">01.01.2026",'Завершенные данные ДГД'!C:C,Доначисление!A7)/1000000 -> 1859.4109 | L7: =K7-J7 -> -0.25967877 | M7: =I7-H7 -> 1691.0571 | N7: =I7/H7 -> 11.044666 | O7: =IF(N7<90%,0,IF(N7<=99.999999%,5,IF(N7>=100%,10,""))) -> 10 | P7: 1709.3888 | Q7: =I7/P7*100 -> 108.77636 | R7: =I7-P7 -> 150.02211 | S7: 1002.7767 | T7: =I7/S7*100 -> 185.42621
A8: 06xx | B8: =RANK(N8,$N$6:$N$25,0) -> 4 | C8: Актюбинская | D8: 2.9855147 | E8: 11448.066 | F8: =E8*120% -> 13737.68 | G8: =D8%*$F$26 -> 5247.2171 | H8: 524.72171 | I8: =MIN(J8:K8) -> 2608.9058 | J8: =SUMIFS('Завершенные ИНИС и ИСНА'!U:U,'Завершенные ИНИС и ИСНА'!T:T,"УНА",'Завершенные ИНИС и ИСНА'!C:C,Доначисление!A8)/1000000 -> 2608.9058 | K8: =SUMIFS('Завершенные данные ДГД'!AH:AH,'Завершенные данные ДГД'!AS:AS,"УНА",'Завершенные данные ДГД'!L:L,">01.01.2026",'Завершенные данные ДГД'!C:C,Доначисление!A8)/1000000 -> 2609.2027 | L8: =K8-J8 -> 0.2968797 | M8: =I8-H8 -> 2084.1841 | N8: =I8/H8 -> 4.9719799 | O8: =IF(N8<90%,0,IF(N8<=99.999999%,5,IF(N8>=100%,10,""))) -> 10 | P8: 2454.0845 | Q8: =I8/P8*100 -> 106.30872 | R8: =I8-P8 -> 154.8213 | S8: 2940.4076 | T8: =I8/S8*100 -> 88.725991
A9: 71xx | B9: =RANK(N9,$N$6:$N$25,0) -> 15 | C9: область Абай | D9: 1.3477265 | E9: 2720.6351 | F9: =E9*120% -> 3264.7622 | G9: =D9%*$F$26 -> 2368.7083 | H9: 236.87083 | I9: =MIN(J9:K9) -> 241.51539 | J9: =SUMIFS('Завершенные ИНИС и ИСНА'!U:U,'Завершенные ИНИС и ИСНА'!T:T,"УНА",'Завершенные ИНИС и ИСНА'!C:C,Доначисление!A9)/1000000 -> 241.51539 | K9: =SUMIFS('Завершенные данные ДГД'!AH:AH,'Завершенные данные ДГД'!AS:AS,"УНА",'Завершенные данные ДГД'!L:L,">01.01.2026",'Завершенные данные ДГД'!C:C,Доначисление!A9)/1000000 -> 241.5434 | L9: =K9-J9 -> 0.02801262 | M9: =I9-H9 -> 4.6445619 | N9: =I9/H9 -> 1.019608 | O9: =IF(N9<90%,0,IF(N9<=99.999999%,5,IF(N9>=100%,10,""))) -> 10 | P9: 1.206162 | Q9: =I9/P9*100 -> 20023.462 | R9: =I9-P9 -> 240.30923 | S9: 749.06747 | T9: =I9/S9*100 -> 32.242141
A10: 21xx | B10: =RANK(N10,$N$6:$N$25,0) -> 17 | C10: Жамбылская | D10: 1.3672005 | E10: 2764.1785 | F10: =E10*120% -> 3317.0141 | G10: =D10%*$F$26 -> 2402.935 | H10: 240.2935 | I10: =MIN(J10:K10) -> 39.948959 | J10: =SUMIFS('Завершенные ИНИС и ИСНА'!U:U,'Завершенные ИНИС и ИСНА'!T:T,"УНА",'Завершенные ИНИС и ИСНА'!C:C,Доначисление!A10)/1000000 -> 40.145475 | K10: =SUMIFS('Завершенные данные ДГД'!AH:AH,'Завершенные данные ДГД'!AS:AS,"УНА",'Завершенные данные ДГД'!L:L,">01.01.2026",'Завершенные данные ДГД'!C:C,Доначисление!A10)/1000000 -> 39.948959 | L10: =K10-J10 -> -0.19651583 | M10: =I10-H10 -> -200.34454 | N10: =I10/H10 -> 0.16625068 | O10: =IF(N10<90%,0,IF(N10<=99.999999%,5,IF(N10>=100%,10,""))) -> 0 | P10: 5.202512 | Q10: =I10/P10*100 -> 767.87826 | R10: =I10-P10 -> 34.746447 | S10: 1517.7456 | T10: =I10/S10*100 -> 2.6321248
A11: 59xx | B11: =RANK(N11,$N$6:$N$25,0) -> 2 | C11: г.Шымкент | D11: 3.0326739 | E11: 7812.3703 | F11: =E11*120% -> 9374.8444 | G11: =D11%*$F$26 -> 5330.1022 | H11: 533.01022 | I11: =MIN(J11:K11) -> 4102.124 | J11: =SUMIFS('Завершенные ИНИС и ИСНА'!U:U,'Завершенные ИНИС и ИСНА'!T:T,"УНА",'Завершенные ИНИС и ИСНА'!C:C,Доначисление!A11)/1000000 -> 4102.3672 | K11: =SUMIFS('Завершенные данные ДГД'!AH:AH,'Завершенные данные ДГД'!AS:AS,"УНА",'Завершенные данные ДГД'!L:L,">01.01.2026",'Завершенные данные ДГД'!C:C,Доначисление!A11)/1000000 -> 4102.124 | L11: =K11-J11 -> -0.2431344 | M11: =I11-H11 -> 3569.1138 | N11: =I11/H11 -> 7.6961452 | O11: =IF(N11<90%,0,IF(N11<=99.999999%,5,IF(N11>=100%,10,""))) -> 10 | P11: 3590.2077 | Q11: =I11/P11*100 -> 114.25868 | R11: =I11-P11 -> 511.91634 | S11: 3801.0442 | T11: =I11/S11*100 -> 107.92098
A12: 33xx | B12: =RANK(N12,$N$6:$N$25,0) -> 13 | C12: Кызылординская | D12: 2.029 | E12: 4541.9624 | F12: =E12*120% -> 5450.3549 | G12: =D12%*$F$26 -> 3566.0865 | H12: 356.60865 | I12: =MIN(J12:K12) -> 407.49043 | J12: =SUMIFS('Завершенные ИНИС и ИСНА'!U:U,'Завершенные ИНИС и ИСНА'!T:T,"УНА",'Завершенные ИНИС и ИСНА'!C:C,Доначисление!A12)/1000000 -> 407.65693 | K12: =SUMIFS('Завершенные данные ДГД'!AH:AH,'Завершенные данные ДГД'!AS:AS,"УНА",'Завершенные данные ДГД'!L:L,">01.01.2026",'Завершенные данные ДГД'!C:C,Доначисление!A12)/1000000 -> 407.49043 | L12: =K12-J12 -> -0.16649927 | M12: =I12-H12 -> 50.881779 | N12: =I12/H12 -> 1.1426824 | O12: =IF(N12<90%,0,IF(N12<=99.999999%,5,IF(N12>=100%,10,""))) -> 10 | P12: 33.364663 | Q12: =I12/P12*100 -> 1221.3234 | R12: =I12-P12 -> 374.12577 | S12: 454.12563 | T12: =I12/S12*100 -> 89.73077
A13: 48xx | B13: =RANK(N13,$N$6:$N$25,0) -> 6 | C13: СКО | D13: 1.1647603 | E13: 1116.0235 | F13: =E13*120% -> 1339.2282 | G13: =D13%*$F$26 -> 2047.1346 | H13: 204.71346 | I13: =MIN(J13:K13) -> 718.23921 | J13: =SUMIFS('Завершенные ИНИС и ИСНА'!U:U,'Завершенные ИНИС и ИСНА'!T:T,"УНА",'Завершенные ИНИС и ИСНА'!C:C,Доначисление!A13)/1000000 -> 718.23921 | K13: =SUMIFS('Завершенные данные ДГД'!AH:AH,'Завершенные данные ДГД'!AS:AS,"УНА",'Завершенные данные ДГД'!L:L,">01.01.2026",'Завершенные данные ДГД'!C:C,Доначисление!A13)/1000000 -> 718.23921 | L13: =K13-J13 -> 0 | M13: =I13-H13 -> 513.52576 | N13: =I13/H13 -> 3.50851 | O13: =IF(N13<90%,0,IF(N13<=99.999999%,5,IF(N13>=100%,10,""))) -> 10 | P13: 101.80685 | Q13: =I13/P13*100 -> 705.492 | R13: =I13-P13 -> 616.43236 | S13: 623.26405 | T13: =I13/S13*100 -> 115.23835
A14: 43xx | B14: =RANK(N14,$N$6:$N$25,0) -> 3 | C14: Мангистауская | D14: 2.8331699 | E14: 4907.9639 | F14: =E14*120% -> 5889.5567 | G14: =D14%*$F$26 -> 4979.4622 | H14: 497.94622 | I14: =MIN(J14:K14) -> 2808.6616 | J14: =SUMIFS('Завершенные ИНИС и ИСНА'!U:U,'Завершенные ИНИС и ИСНА'!T:T,"УНА",'Завершенные ИНИС и ИСНА'!C:C,Доначисление!A14)/1000000 -> 2985.8145 | K14: =SUMIFS('Завершенные данные ДГД'!AH:AH,'Завершенные данные ДГД'!AS:AS,"УНА",'Завершенные данные ДГД'!L:L,">01.01.2026",'Завершенные данные ДГД'!C:C,Доначисление!A14)/1000000 -> 2808.6616 | L14: =K14-J14 -> -177.15289 | M14: =I14-H14 -> 2310.7154 | N14: =I14/H14 -> 5.6404918 | O14: =IF(N14<90%,0,IF(N14<=99.999999%,5,IF(N14>=100%,10,""))) -> 10 | P14: 507.77715 | Q14: =I14/P14*100 -> 553.12879 | R14: =I14-P14 -> 2300.8844 | S14: 1257.9869 | T14: =I14/S14*100 -> 223.26637
A15: 39xx | B15: =RANK(N15,$N$6:$N$25,0) -> 12 | C15: Костанайская | D15: 2.0764292 | E15: 2093.6257 | F15: =E15*120% -> 2512.3509 | G15: =D15%*$F$26 -> 3649.4461 | H15: 364.94461 | I15: =MIN(J15:K15) -> 440.40228 | J15: =SUMIFS('Завершенные ИНИС и ИСНА'!U:U,'Завершенные ИНИС и ИСНА'!T:T,"УНА",'Завершенные ИНИС и ИСНА'!C:C,Доначисление!A15)/1000000 -> 440.40228 | K15: =SUMIFS('Завершенные данные ДГД'!AH:AH,'Завершенные данные ДГД'!AS:AS,"УНА",'Завершенные данные ДГД'!L:L,">01.01.2026",'Завершенные данные ДГД'!C:C,Доначисление!A15)/1000000 -> 440.43752 | L15: =K15-J15 -> 0.03523728 | M15: =I15-H15 -> 75.45767 | N15: =I15/H15 -> 1.2067647 | O15: =IF(N15<90%,0,IF(N15<=99.999999%,5,IF(N15>=100%,10,""))) -> 10 | P15: 380.43948 | Q15: =I15/P15*100 -> 115.76146 | R15: =I15-P15 -> 59.962801 | S15: 891.17098 | T15: =I15/S15*100 -> 49.418382
A16: 15xx | B16: =RANK(N16,$N$6:$N$25,0) -> 18 | C16: Атырауская | D16: 5.7606993 | E16: 6315.985 | F16: =E16*120% -> 7579.182 | G16: =D16%*$F$26 -> 10124.767 | H16: 1012.4767 | I16: =MIN(J16:K16) -> 83.797924 | J16: =SUMIFS('Завершенные ИНИС и ИСНА'!U:U,'Завершенные ИНИС и ИСНА'!T:T,"УНА",'Завершенные ИНИС и ИСНА'!C:C,Доначисление!A16)/1000000 -> 83.797924 | K16: =SUMIFS('Завершенные данные ДГД'!AH:AH,'Завершенные данные ДГД'!AS:AS,"УНА",'Завершенные данные ДГД'!L:L,">01.01.2026",'Завершенные данные ДГД'!C:C,Доначисление!A16)/1000000 -> 83.809821 | L16: =K16-J16 -> 0.01189732 | M16: =I16-H16 -> -928.67874 | N16: =I16/H16 -> 0.082765289 | O16: =IF(N16<90%,0,IF(N16<=99.999999%,5,IF(N16>=100%,10,""))) -> 0 | P16: 36.650885 | Q16: =I16/P16*100 -> 228.6382 | R16: =I16-P16 -> 47.147039 | S16: 914.12818 | T16: =I16/S16*100 -> 9.1669774
A17: 60xx | B17: =RANK(N17,$N$6:$N$25,0) -> 7 | C17: г.Алматы | D17: 34.155969 | E17: 39277.384 | F17: =E17*120% -> 47132.861 | G17: =D17%*$F$26 -> 60031.118 | H17: 6003.1118 | I17: =MIN(J17:K17) -> 18998.209 | J17: =SUMIFS('Завершенные ИНИС и ИСНА'!U:U,'Завершенные ИНИС и ИСНА'!T:T,"УНА",'Завершенные ИНИС и ИСНА'!C:C,Доначисление!A17)/1000000 -> 18998.209 | K17: =SUMIFS('Завершенные данные ДГД'!AH:AH,'Завершенные данные ДГД'!AS:AS,"УНА",'Завершенные данные ДГД'!L:L,">01.01.2026",'Завершенные данные ДГД'!C:C,Доначисление!A17)/1000000 -> 18998.567 | L17: =K17-J17 -> 0.35828207 | M17: =I17-H17 -> 12995.097 | N17: =I17/H17 -> 3.1647269 | O17: =IF(N17<90%,0,IF(N17<=99.999999%,5,IF(N17>=100%,10,""))) -> 10 | P17: 4984.1401 | Q17: =I17/P17*100 -> 381.17325 | R17: =I17-P17 -> 14014.069 | S17: 9285.3339 | T17: =I17/S17*100 -> 204.60448
... A25: 03xx | B25: =RANK(N25,$N$6:$N$25,0) -> 20 | C25: Акмолинская | D25: 2.0551297 | E25: 1659.8398 | F25: =E25*120% -> 1991.8077 | G25: =D25%*$F$26 -> 3612.0109 | H25: 361.20109 | I25: =MIN(J25:K25) -> 4.635403 | J25: =SUMIFS('Завершенные ИНИС и ИСНА'!U:U,'Завершенные ИНИС и ИСНА'!T:T,"УНА",'Завершенные ИНИС и ИСНА'!C:C,Доначисление!A25)/1000000 -> 4.6354078 | K25: =SUMIFS('Завершенные данные ДГД'!AH:AH,'Завершенные данные ДГД'!AS:AS,"УНА",'Завершенные данные ДГД'!L:L,">01.01.2026",'Завершенные данные ДГД'!C:C,Доначисление!A25)/1000000 -> 4.635403 | L25: =K25-J25 -> -4.77e-06 | M25: =I25-H25 -> -356.56569 | N25: =I25/H25 -> 0.012833303 | O25: =IF(N25<90%,0,IF(N25<=99.999999%,5,IF(N25>=100%,10,""))) -> 0 | P25: 4.635403 | Q25: =I25/P25*100 -> 100 | R25: =I25-P25 -> 0 | S25: 154.69126 | T25: =I25/S25*100 -> 2.9965512
B26: Итого | C26: КГД | D26: =SUM(D6:D25) -> 100 | E26: =SUM(E6:E25) -> 146463.22 | F26: =SUM(F6:F25) -> 175755.86 | G26: =SUM(G6:G25) -> 175755.86 | H26: =SUM(H6:H25) -> 17575.586 | I26: =SUM(I6:I25) -> 42066.551 | J26: =SUM(J6:J25) -> 42245.761 | K26: =SUM(K6:K25) -> 42068.52 | L26: =SUM(L6:L25) -> -177.24126 | M26: =I26-H26 -> 24490.965 | N26: =I26/H26 -> 2.3934651 | O26: =IF(N26<90%,0,IF(N26<=99.999999%,5,IF(N26>=100%,10,""))) -> 10 | P26: =SUM(P6:P25) -> 19791.79 | Q26: =I26/P26*100 -> 212.54547 | R26: =SUM(R6:R25) -> 22274.762 | S26: =SUM(S6:S25) -> 33013.641 | T26: =I26/S26*100 -> 127.42173

Sheet Лист1
B2: Динамика доначисленных сумм на 01.04.2026
I3: млн.тг.
B4: № | C4: ДГД | D4: Доля в % по 4 КБК | E4: Доначислено на 01.01.2026 | F4: Темп роста +120% | G4: KPI на 01.01.2027 | H4: KPI на 01.04.2026 | I4: Факт на 01.04.2026 | J4: Исполнение KPI | L4: Баллы | M4: Доначислено на 01.04.2025 | N4: Темп роста
J5: в сумме | K5: в %
A6: 70xx | B6: 1 | C6: область Жетісу | D6: 0.95788406 | E6: 3866.5806 | F6: 4639.8967 | G6: 1683.5374 | H6: 168.35374 | I6: 1859.4109 | J6: 1691.0571 | K6: 11.044666 | L6: 10 | M6: 1002.7767 | N6: 185.42621
A7: 59xx | B7: 2 | C7: г.Шымкент | D7: 3.0326739 | E7: 7812.3703 | F7: 9374.8444 | G7: 5330.1022 | H7: 533.01022 | I7: 4102.124 | J7: 3569.1138 | K7: 7.6961452 | L7: 10 | M7: 3801.0442 | N7: 107.92098
A8: 43xx | B8: 3 | C8: Мангистауская | D8: 2.8331699 | E8: 4907.9639 | F8: 5889.5567 | G8: 4979.4622 | H8: 497.94622 | I8: 2808.6616 | J8: 2310.7154 | K8: 5.6404918 | L8: 10 | M8: 1257.9869 | N8: 223.26637
A9: 06xx | B9: 4 | C9: Актюбинская | D9: 2.9855147 | E9: 11448.066 | F9: 13737.68 | G9: 5247.2171 | H9: 524.72171 | I9: 2608.9058 | J9: 2084.1841 | K9: 4.9719799 | L9: 10 | M9: 2940.4076 | N9: 88.725991
A10: 30xx | B10: 5 | C10: Карагандинская | D10: 4.2474376 | E10: 4695.1737 | F10: 5634.2085 | G10: 7465.1205 | H10: 746.51205 | I10: 3604.2166 | J10: 2857.7045 | K10: 4.8280755 | L10: 10 | M10: 1174.7914 | N10: 306.79629
A11: 48xx | B11: 6 | C11: СКО | D11: 1.1647603 | E11: 1116.0235 | F11: 1339.2282 | G11: 2047.1346 | H11: 204.71346 | I11: 718.23921 | J11: 513.52576 | K11: 3.50851 | L11: 10 | M11: 623.26405 | N11: 115.23835
A12: 09xx | B12: 7 | C12: Алматинская | D12: 3.9059212 | E12: 12006.997 | F12: 14408.397 | G12: 6864.8855 | H12: 686.48855 | I12: 1511.0814 | J12: 824.59283 | K12: 2.2011749 | L12: 10 | M12: 801.2529 | N12: 188.58982
A13: 45xx | B13: 8 | C13: Павлодарская | D13: 2.9290283 | E13: 4518.6039 | F13: 5422.3247 | G13: 5147.939 | H13: 514.7939 | I13: 1070.5822 | J13: 555.78834 | K13: 2.0796327 | L13: 10 | M13: 709.06418 | N13: 150.98524
A14: 18xx | B14: 9 | C14: ВКО | D14: 2.8241989 | E14: 2538.0597 | F14: 3045.6717 | G14: 4963.6951 | H14: 496.36951 | I14: 704.02056 | J14: 207.65106 | K14: 1.4183397 | L14: 10 | M14: 152.36159 | N14: 462.07221
A15: 72xx | B15: 10 | C15: Область Ұлытау | D15: 0.69154453 | E15: 830.55508 | F15: 996.6661 | G15: 1215.43 | H15: 121.543 | I15: 158.85571 | J15: 37.312709 | K15: 1.3069918 | L15: 10 | M15: 221.13674 | N15: 71.835965
A16: 39xx | B16: 11 | C16: Костанайская | D16: 2.0764292 | E16: 2093.6257 | F16: 2512.3509 | G16: 3649.4461 | H16: 364.94461 | I16: 440.40228 | J16: 75.45767 | K16: 1.2067647 | L16: 10 | M16: 891.17098 | N16: 49.418382
A17: 33xx | B17: 12 | C17: Кызылординская | D17: 2.029 | E17: 4541.9624 | F17: 5450.3549 | G17: 3566.0865 | H17: 356.60865 | I17: 407.49043 | J17: 50.881779 | K17: 1.1426824 | L17: 10 | M17: 454.12563 | N17: 89.73077
... A25: 03xx | B25: 20 | C25: Акмолинская | D25: 2.0551297 | E25: 1659.8398 | F25: 1991.8077 | G25: 3612.0109 | H25: 361.20109 | I25: 4.635403 | J25: -356.56569 | K25: 0.012833303 | L25: 0 | M25: 154.69126 | N25: 2.9965512
B26: Итого | D26: 100 | E26: 146463.22 | F26: 175755.86 | G26: 175755.86 | H26: 17575.586 | I26: 29135.957 | J26: 11560.371 | K26: 1.6577517 | L26: 10 | M26: 33013.641 | N26: 127

Sheet Взыскание
B2: Структура взысканных сумм на 01.04.2026
I3: млн.тг.
B4: № | C4: ДГД | D4: Доля в % по 4 КБК | E4: Взыскано на 01.01.2026 | F4: Темп роста +120% | G4: KPI на 01.01.2027 | H4: KPI на 01.04.2026 | I4: Факт на 01.04.2026 | J4: Исполнение KPI | L4: Баллы | M4: Взыскано на 01.03.2026 | N4: Темп роста | O4: Откл | P4: Взыскано на 01.04.2025 | Q4: Темп роста
J5: в сумме | K5: в %
A6: 21xx | B6: =RANK(K6,$K$6:$K$25,0) -> 1 | C6: Жамбылская | D6: 1.3672005 | E6: 2619.5385 | F6: =E6*120% -> 3143.4462 | G6: =D6%*$F$26 -> 931.52772 | H6: 93.152772 | I6: =SUMIFS('Завершенные данные ДГД'!AM:AM,'Завершенные данные ДГД'!AT:AT,"да",'Завершенные данные ДГД'!C:C,Взыскание!A6)/1000000 -> 854.66994 | J6: =I6-H6 -> 761.51716 | K6: =I6/H6 -> 9.1749276 | L6: =IF(K6<80%,0,IF(K6<90%,10,IF(K6<=99.9%,20,IF(K6>=100%,40,"")))) -> 40 | M6: 812.30452 | N6: =I6/M6*100 -> 105.21546 | O6: =I6-M6 -> 42.36542 | P6: 383.64331 | Q6: =I6/P6*100 -> 222.77723
A7: 59xx | B7: =RANK(K7,$K$6:$K$25,0) -> 12 | C7: г.Шымкент | D7: 3.0326739 | E7: 2050.2551 | F7: =E7*120% -> 2460.3061 | G7: =D7%*$F$26 -> 2066.2806 | H7: 206.62806 | I7: =SUMIFS('Завершенные данные ДГД'!AM:AM,'Завершенные данные ДГД'!AT:AT,"да",'Завершенные данные ДГД'!C:C,Взыскание!A7)/1000000 -> 255.38722 | J7: =I7-H7 -> 48.759161 | K7: =I7/H7 -> 1.2359755 | L7: =IF(K7<80%,0,IF(K7<90%,10,IF(K7<=99.9%,20,IF(K7>=100%,40,"")))) -> 40 | M7: 159.15669 | N7: =I7/M7*100 -> 160.46277 | O7: =I7-M7 -> 96.230533 | P7: 1767.5859 | Q7: =I7/P7*100 -> 14.448363
A8: 33xx | B8: =RANK(K8,$K$6:$K$25,0) -> 13 | C8: Кызылординская | D8: 2.029 | E8: 2471.0836 | F8: =E8*120% -> 2965.3004 | G8: =D8%*$F$26 -> 1382.4379 | H8: 138.24379 | I8: =SUMIFS('Завершенные данные ДГД'!AM:AM,'Завершенные данные ДГД'!AT:AT,"да",'Завершенные данные ДГД'!C:C,Взыскание!A8)/1000000 -> 165.0742 | J8: =I8-H8 -> 26.830409 | K8: =I8/H8 -> 1.1940804 | L8: =IF(K8<80%,0,IF(K8<90%,10,IF(K8<=99.9%,20,IF(K8>=100%,40,"")))) -> 40 | M8: 76.36711 | N8: =I8/M8*100 -> 216.15876 | O8: =I8-M8 -> 88.707088 | P8: 161.87218 | Q8: =I8/P8*100 -> 101.97812
A9: 43xx | B9: =RANK(K9,$K$6:$K$25,0) -> 20 | C9: Мангистауская | D9: 2.8331699 | E9: 2262.2558 | F9: =E9*120% -> 2714.707 | G9: =D9%*$F$26 -> 1930.3506 | H9: 193.03506 | I9: =SUMIFS('Завершенные данные ДГД'!AM:AM,'Завершенные данные ДГД'!AT:AT,"да",'Завершенные данные ДГД'!C:C,Взыскание!A9)/1000000 -> 166.45599 | J9: =I9-H9 -> -26.579068 | K9: =I9/H9 -> 0.86230964 | L9: =IF(K9<80%,0,IF(K9<90%,10,IF(K9<=99.9%,20,IF(K9>=100%,40,"")))) -> 10 | M9: 66.867593 | N9: =I9/M9*100 -> 248.93373 | O9: =I9-M9 -> 99.588401 | P9: 408.06508 | Q9: =I9/P9*100 -> 40.791531
A10: 06xx | B10: =RANK(K10,$K$6:$K$25,0) -> 3 | C10: Актюбинская | D10: 2.9855147 | E10: 1837.3025 | F10: =E10*120% -> 2204.763 | G10: =D10%*$F$26 -> 2034.1491 | H10: 203.41491 | I10: =SUMIFS('Завершенные данные ДГД'!AM:AM,'Завершенные данные ДГД'!AT:AT,"да",'Завершенные данные ДГД'!C:C,Взыскание!A10)/1000000 -> 1301.693 | J10: =I10-H10 -> 1098.2781 | K10: =I10/H10 -> 6.3992016 | L10: =IF(K10<80%,0,IF(K10<90%,10,IF(K10<=99.9%,20,IF(K10>=100%,40,"")))) -> 40 | M10: 1261.4166 | N10: =I10/M10*100 -> 103.19295 | O10: =I10-M10 -> 40.276386 | P10: 887.47805 | Q10: =I10/P10*100 -> 146.67327
A11: 39xx | B11: =RANK(K11,$K$6:$K$25,0) -> 18 | C11: Костанайская | D11: 2.0764292 | E11: 1106.1252 | F11: =E11*120% -> 1327.3502 | G11: =D11%*$F$26 -> 1414.7533 | H11: 141.47533 | I11: =SUMIFS('Завершенные данные ДГД'!AM:AM,'Завершенные данные ДГД'!AT:AT,"да",'Завершенные данные ДГД'!C:C,Взыскание!A11)/1000000 -> 141.16053 | J11: =I11-H11 -> -0.3147962 | K11: =I11/H11 -> 0.9977749 | L11: =IF(K11<80%,0,IF(K11<90%,10,IF(K11<=99.9%,20,IF(K11>=100%,40,"")))) -> 20 | M11: 114.05017 | N11: =I11/M11*100 -> 123.77055 | O11: =I11-M11 -> 27.110358 | P11: 444.85742 | Q11: =I11/P11*100 -> 31.731635
A12: 18xx | B12: =RANK(K12,$K$6:$K$25,0) -> 5 | C12: ВКО | D12: 2.8241989 | E12: 1737.9054 | F12: =E12*120% -> 2085.4865 | G12: =D12%*$F$26 -> 1924.2383 | H12: 192.42383 | I12: =SUMIFS('Завершенные данные ДГД'!AM:AM,'Завершенные данные ДГД'!AT:AT,"да",'Завершенные данные ДГД'!C:C,Взыскание!A12)/1000000 -> 592.34982 | J12: =I12-H12 -> 399.92599 | K12: =I12/H12 -> 3.07836 | L12: =IF(K12<80%,0,IF(K12<90%,10,IF(K12<=99.9%,20,IF(K12>=100%,40,"")))) -> 40 | M12: 477.41027 | N12: =I12/M12*100 -> 124.07563 | O12: =I12-M12 -> 114.93955 | P12: 411.74894 | Q12: =I12/P12*100 -> 143.86189
A13: 71xx | B13: =RANK(K13,$K$6:$K$25,0) -> 17 | C13: область Абай | D13: 1.3477265 | E13: 765.32661 | F13: =E13*120% -> 918.39193 | G13: =D13%*$F$26 -> 918.2593 | H13: 91.82593 | I13: =SUMIFS('Завершенные данные ДГД'!AM:AM,'Завершенные данные ДГД'!AT:AT,"да",'Завершенные данные ДГД'!C:C,Взыскание!A13)/1000000 -> 92.042939 | J13: =I13-H13 -> 0.21700945 | K13: =I13/H13 -> 1.0023633 | L13: =IF(K13<80%,0,IF(K13<90%,10,IF(K13<=99.9%,20,IF(K13>=100%,40,"")))) -> 40 | M13: 15.434638 | N13: =I13/M13*100 -> 596.34012 | O13: =I13-M13 -> 76.608301 | P13: 30.063802 | Q13: =I13/P13*100 -> 306.15868
A14: 58xx | B14: =RANK(K14,$K$6:$K$25,0) -> 14 | C14: Туркестанская | D14: 2.614949 | E14: 903.24458 | F14: =E14*120% -> 1083.8935 | G14: =D14%*$F$26 -> 1781.6681 | H14: 178.16681 | I14: =SUMIFS('Завершенные данные ДГД'!AM:AM,'Завершенные данные ДГД'!AT:AT,"да",'Завершенные данные ДГД'!C:C,Взыскание!A14)/1000000 -> 197.50011 | J14: =I14-H14 -> 19.333304 | K14: =I14/H14 -> 1.1085124 | L14: =IF(K14<80%,0,IF(K14<90%,10,IF(K14<=99.9%,20,IF(K14>=100%,40,"")))) -> 40 | M14: 59.805365 | N14: =I14/M14*100 -> 330.23812 | O14: =I14-M14 -> 137.69475 | P14: 248.91945 | Q14: =I14/P14*100 -> 79.342982
A15: 30xx | B15: =RANK(K15,$K$6:$K$25,0) -> 8 | C15: Карагандинская | D15: 4.2474376 | E15: 2804.0401 | F15: =E15*120% -> 3364.8482 | G15: =D15%*$F$26 -> 2893.947 | H15: 289.3947 | I15: =SUMIFS('Завершенные данные ДГД'!AM:AM,'Завершенные данные ДГД'!AT:AT,"да",'Завершенные данные ДГД'!C:C,Взыскание!A15)/1000000 -> 551.82157 | J15: =I15-H15 -> 262.42686 | K15: =I15/H15 -> 1.9068129 | L15: =IF(K15<80%,0,IF(K15<90%,10,IF(K15<=99.9%,20,IF(K15>=100%,40,"")))) -> 40 | M15: 223.98907 | N15: =I15/M15*100 -> 246.36094 | O15: =I15-M15 -> 327.8325 | P15: 945.74625 | Q15: =I15/P15*100 -> 58.347741
A16: 70xx | B16: =RANK(K16,$K$6:$K$25,0) -> 10 | C16: область Жетісу | D16: 0.95788406 | E16: 496.48554 | F16: =E16*120% -> 595.78264 | G16: =D16%*$F$26 -> 652.64426 | H16: 65.264426 | I16: =SUMIFS('Завершенные данные ДГД'!AM:AM,'Завершенные данные ДГД'!AT:AT,"да",'Завершенные данные ДГД'!C:C,Взыскание!A16)/1000000 -> 94.391891 | J16: =I16-H16 -> 29.127465 | K16: =I16/H16 -> 1.4462993 | L16: =IF(K16<80%,0,IF(K16<90%,10,IF(K16<=99.9%,20,IF(K16>=100%,40,"")))) -> 40 | M16: 40.051735 | N16: =I16/M16*100 -> 235.67491 | O16: =I16-M16 -> 54.340156 | P16: 32.506977 | Q16: =I16/P16*100 -> 290.37425
A17: 45xx | B17: =RANK(K17,$K$6:$K$25,0) -> 15 | C17: Павлодарская | D17: 2.9290283 | E17: 1354.14 | F17: =E17*120% -> 1624.968 | G17: =D17%*$F$26 -> 1995.6627 | H17: 199.56627 | I17: =SUMIFS('Завершенные данные ДГД'!AM:AM,'Завершенные данные ДГД'!AT:AT,"да",'Завершенные данные ДГД'!C:C,Взыскание!A17)/1000000 -> 208.333 | J17: =I17-H17 -> 8.7667204 | K17: =I17/H17 -> 1.0439289 | L17: =IF(K17<80%,0,IF(K17<90%,10,IF(K17<=99.9%,20,IF(K17>=100%,40,"")))) -> 40 | M17: 56.978891 | N17: =I17/M17*100 -> 365.63189 | O17: =I17-M17 -> 151.3541 | P17: 12.346654 | Q17: =I17/P17*100 -> 1687.364
... A25: 62xx | B25: =RANK(K25,$K$6:$K$25,0) -> 19 | C25: г.Астана | D25: 21.109391 | E25: 9013.7223 | F25: =E25*120% -> 10816.467 | G25: =D25%*$F$26 -> 14382.662 | H25: 1438.2662 | I25: =SUMIFS('Завершенные данные ДГД'!AM:AM,'Завершенные данные ДГД'!AT:AT,"да",'Завершенные данные ДГД'!C:C,Взыскание!A25)/1000000 -> 1316.3046 | J25: =I25-H25 -> -121.9616 | K25: =I25/H25 -> 0.91520234 | L25: =IF(K25<80%,0,IF(K25<90%,10,IF(K25<=99.9%,20,IF(K25>=100%,40,"")))) -> 20 | M25: 325.0477 | N25: =I25/M25*100 -> 404.95736 | O25: =I25-M25 -> 991.25689 | P25: 16.806 | Q25: =I25/P25*100 -> 7832.3491
B26: Итого | C26: КГД | D26: =SUM(D6:D25) -> 100 | E26: =SUM(E6:E25) -> 56778.293 | F26: =SUM(F6:F25) -> 68133.951 | G26: =SUM(G6:G25) -> 68133.951 | H26: =SUM(H6:H25) -> 6813.3951 | I26: =SUM(I6:I25) -> 15205.795 | J26: =I26-H26 -> 8392.4001 | K26: =I26/H26 -> 2.2317501 | L26: =IF(K26<80%,0,IF(K26<90%,10,IF(K26<=99.9%,20,IF(K26>=100%,40,"")))) -> 40 | M26: =SUM(M6:M25) -> 6143.3193 | N26: =I26/M26*100 -> 247.51758 | O26: =SUM(O6:O25) -> 9062.4759 | P26: =SUM(P6:P25) -> 14031.418 | Q26: =I26/P26*100 -> 108.36963

Sheet Лист2
B2: Структура взысканных сумм на 01.04.2026
H3: млн.тг.
B4: № | C4: ДГД | D4: Доля в % по 4 КБК | E4: Взыскано на 01.01.2026 | F4: Темп роста +120% | G4: KPI на 01.01.2027 | H4: KPI на 01.04.2026 | I4: Факт на 01.04.2026 | J4: Исполнение KPI | L4: Баллы | M4: Взыскано на 01.04.2025 | N4: Темп роста
J5: в сумме | K5: в %
A6: 21xx | B6: 1 | C6: Жамбылская | D6: 1.3672005 | E6: 2619.5385 | F6: 3143.4462 | G6: 931.52772 | H6: 93.152772 | I6: 854.66994 | J6: 761.51716 | K6: 9.1749276 | L6: 40 | M6: 383.64331 | N6: 222.77723
A7: 03xx | B7: 2 | C7: Акмолинская | D7: 2.0551297 | E7: 789.06613 | F7: 946.87936 | G7: 1400.2411 | H7: 140.02411 | I7: 961.45756 | J7: 821.43345 | K7: 6.8663716 | L7: 40 | M7: 277.6975 | N7: 346.22478
A8: 06xx | B8: 3 | C8: Актюбинская | D8: 2.9855147 | E8: 1837.3025 | F8: 2204.763 | G8: 2034.1491 | H8: 203.41491 | I8: 1301.693 | J8: 1098.2781 | K8: 6.3992016 | L8: 40 | M8: 887.47805 | N8: 146.67327
A9: 27xx | B9: 4 | C9: ЗКО | D9: 1.9113729 | E9: 1279.9542 | F9: 1535.9451 | G9: 1302.2939 | H9: 130.22939 | I9: 402.34887 | J9: 272.11948 | K9: 3.0895398 | L9: 40 | M9: 202.32816 | N9: 198.85955
A10: 18xx | B10: 5 | C10: ВКО | D10: 2.8241989 | E10: 1737.9054 | F10: 2085.4865 | G10: 1924.2383 | H10: 192.42383 | I10: 592.34982 | J10: 399.92599 | K10: 3.07836 | L10: 40 | M10: 411.74894 | N10: 143.86189
A11: 15xx | B11: 6 | C11: Атырауская | D11: 5.7606993 | E11: 3303.7358 | F11: 3964.483 | G11: 3924.9921 | H11: 392.49921 | I11: 1174.8994 | J11: 782.40024 | K11: 2.9933804 | L11: 40 | M11: 228.8861 | N11: 513.31183
A12: 60xx | B12: 7 | C12: г.Алматы | D12: 34.155969 | E12: 17830.632 | F12: 21396.759 | G12: 23271.811 | H12: 2327.1811 | I12: 6208.7656 | J12: 3881.5844 | K12: 2.667934 | L12: 40 | M12: 7265.4486 | N12: 85.456052
A13: 30xx | B13: 8 | C13: Карагандинская | D13: 4.2474376 | E13: 2804.0401 | F13: 3364.8482 | G13: 2893.947 | H13: 289.3947 | I13: 551.82157 | J13: 262.42686 | K13: 1.9068129 | L13: 40 | M13: 945.74625 | N13: 58.347741
A14: 48xx | B14: 9 | C14: СКО | D14: 1.1647603 | E14: 669.59727 | F14: 803.51672 | G14: 793.59724 | H14: 79.359724 | I14: 139.63351 | J14: 60.273789 | K14: 1.759501 | L14: 40 | M14: 220.76463 | N14: 63.249948
A15: 70xx | B15: 10 | C15: область Жетісу | D15: 0.95788406 | E15: 496.48554 | F15: 595.78264 | G15: 652.64426 | H15: 65.264426 | I15: 94.391891 | J15: 29.127465 | K15: 1.4462993 | L15: 40 | M15: 32.506977 | N15: 290.37425
A16: 09xx | B16: 11 | C16: Алматинская | D16: 3.9059212 | E16: 2999.96 | F16: 3599.9521 | G16: 2661.2585 | H16: 266.12585 | I16: 333.55386 | J16: 67.428019 | K16: 1.2533689 | L16: 40 | M16: 84.652784 | N16: 394.02586
A17: 59xx | B17: 12 | C17: г.Шымкент | D17: 3.0326739 | E17: 2050.2551 | F17: 2460.3061 | G17: 2066.2806 | H17: 206.62806 | I17: 255.38722 | J17: 48.759161 | K17: 1.2359755 | L17: 40 | M17: 1767.5859 | N17: 14.448363
... A20: 45xx | B20: 15 | C20: Павлодарская | D20: 2.9290283 | E20: 1354.14 | F20: 1624.968 | G20: 1995.6627 | H20: 199.56627 | I20: 208.333 | J20: 8.7667204 | K20: 1.0439289 | L20: 40 | M20: 12.346654 | N20: 1687.364
A21: 72xx | B21: 16 | C21: область Ұлытау | D21: 0.69154453 | E21: 483.92191 | F21: 580.70629 | G21: 471.17661 | H21: 47.117661 | I21: 47.951655 | J21: 0.83399344 | K21: 1.0177002 | L21: 40 | M21: 0 | N21: #DIV/0!
A22: 71xx | B22: 17 | C22: область Абай | D22: 1.3477265 | E22: 765.32661 | F22: 918.39193 | G22: 918.2593 | H22: 91.82593 | I22: 92.042939 | J22: 0.21700945 | K22: 1.0023633 | L22: 40 | M22: 30.063802 | N22: 306.15868
A23: 39xx | B23: 18 | C23: Костанайская | D23: 2.0764292 | E23: 1106.1252 | F23: 1327.3502 | G23: 1414.7533 | H23: 141.47533 | I23: 141.16053 | J23: -0.3147962 | K23: 0.9977749 | L23: 20 | M23: 444.85742 | N23: 31.731635
A24: 62xx | B24: 19 | C24: г.Астана | D24: 21.109391 | E24: 9013.7223 | F24: 10816.467 | G24: 14382.662 | H24: 1438.2662 | I24: 1316.3046 | J24: -121.9616 | K24: 0.91520234 | L24: 20 | M24: 16.806 | N24: 7832.3491
A25: 43xx | B25: 20 | C25: Мангистауская | D25: 2.8331699 | E25: 2262.2558 | F25: 2714.707 | G25: 1930.3506 | H25: 193.03506 | I25: 166.45599 | J25: -26.579068 | K25: 0.86230964 | L25: 10 | M25: 408.06508 | N25: 40.791531
B26: Итого | D26: 100 | E26: 56778.293 | F26: 68133.951 | G26: 68133.951 | H26: 6813.3951 | I26: 15205.795 | J26: 8392.4001 | K26: 2.2317501 | L26: 40 | M26: 14031.418 | N26: 108.36963

Sheet Завершенные данные ДГД
B1: Дата обновления информации | C1: Код ДГД | D1: Департамент | E1: БИН/ИИН | F1: Наименование НП | G1: №предписания | H1: ИСНА-ИНИС | I1: № акта | J1: Дата открытия дела | K1: Дата вручения предписания | L1: Дата окон-о акта | M1: Дата вручения уведомления | N1: Форма проверки | O1: Форма проверки - правильная | R1: Проверяемый период | T1: Ф.И.О. ответственного исполнителя | U1: Субъектность (по данным МНЭ РК) | V1: Мониторинг/Недрапользователь | W1: Фактический вид деятельности (не по ИНИС) | X1: Орган инициирования (заявление НП/Приказ КГД МФ РК/ Список выборочных проверок/в рамках ВУД/требование Прокуратуры и т.д.) | Y1: Приказ КГД МФ РК | AA1: Другие органы | AD1: СГД общее за проверяемый период, в тенге | AE1: КНН средний | AG1: Результаты КЭР | AS1: Управление | AT1: Взыскание Принято - да; не принято - нет | AU1: ДР март | AV1: КЭР прошлые года | AW1: Донач-Взыскание | AX1: Взыскание налог ПП | AY1: Взыскание налог переплата | AZ1: Взыскание пеня ПП | BA1: Взыскание пеня переплата | BB1: Штраф | BC1: Примечание по взысканию | BD1: Донач ИНИС/ИСНА | BE1: Примечание | BF1: ЗПЛ | BG1: ЗПЛ | BH1: ЗПЛ
R2: С (ДД.ММ.ГГГГ) | S2: По (ДД.ММ.ГГГГ) | Y2: Номер | Z2: Дата | AA2: Наименование органа | AB2: Номер | AC2: дата | AG2: КБК | AH2: доначислено всего | AI2: доначислено | AK2: уменьшенный убыток | AL2: штраф | AM2: взыскано всего | AN2: взыскано | BI2: Сумма ДР за март
AI3: налог | AJ3: пеня | AN3: налог | AP3: пеня | AR3: штраф
AN4: ПП | AO4: переплата | AP4: ПП | AQ4: переплата | BF4: 2025г. | BG4: 2024г. | BH4: 2023г.
AH5: =SUBTOTAL(9,AH7:AH1048576) -> 1.3498718e+09 | AI5: =SUBTOTAL(9,AI7:AI1048576) -> 1.2389594e+09 | AJ5: =SUBTOTAL(9,AJ7:AJ1048576) -> 110912482 | AK5: =SUBTOTAL(9,AK7:AK1048576) -> 0 | AL5: =SUBTOTAL(9,AL7:AL1048576) -> 0 | AM5: =SUBTOTAL(9,AM7:AM1048576) -> 148596233 | AN5: =SUBTOTAL(9,AN7:AN1048576) -> 10454725 | AO5: =SUBTOTAL(9,AO7:AO1048576) -> 26949647 | ... AR5: =SUBTOTAL(9,AR7:AR1048576) -> 0 | BD5: фыв | BF5: 3.0089094e+09 | BG5: #N/A | BH5: #N/A | BI5: 2.2574002e+09
A6: 0 | B6: 1 | C6: 2 | D6: 3 | E6: 4 | F6: 5 | G6: 6 | H6: 6 | I6: 7 | J6: 8 | K6: 9 | L6: 10 | M6: 11 | N6: 12 | O6: 12 | R6: 13 | S6: 14 | T6: 15 | U6: 16 | V6: 17 | W6: 18 | X6: 19 | Y6: 20 | Z6: 21 | AA6: 22 | AB6: 23 | AC6: 24 | AD6: 25 | AE6: 26 | AG6: 27 | AH6: 28 | AI6: 29 | AJ6: 30 | AK6: 31 | AL6: 32 | AM6: 33 | AN6: 34 | AO6: 35 | AP6: 36 | AQ6: 37 | AR6: 38 | BI6: фыв
A7: =CONCATENATE(C7,"-",E7,"-",G7) -> 60xx-750125400329-815 | B7: 46107 | C7: 60xx | D7: г.Алматы | E7: 750125400329 | F7: КЕМЕЛЬБАЕВА САНДУГАШ САДЫКОВНА | G7: 815 | H7: ИНИС | I7: 815 | J7: 45432 | K7: 45432 | L7: 45685 | O7: тематическая | R7: 44197 | S7: 45291 | T7: Асхамбаева Г.Х. | U7: нет данных | W7: <нет данных> | X7: Заявление налогоплательщика на ликвидацию | AF7: МБ | AG7: 101202 | AH7: =AI7+AJ7 -> 3864438381 | AI7: 2966066099 | AJ7: 898372282 | AK7: 0 | AL7: 0 | AM7: =AN7+AO7+AP7+AQ7+AR7 -> 4418066099 | AN7: 2926066099 | AO7: 40000000 | AP7: 1452000000 | AQ7: 0 | AR7: 0 | AS7: #N/A | AT7: да | AU7: нет | AV7: правильно | AW7: правильно | AX7: да | AY7: да | AZ7: да | BD7: правильно
A8: =CONCATENATE(C8,"-",E8,"-",G8) -> 15xx-980441001505-23 | B8: 46064 | C8: 15xx | D8: Атырауская | E8: 980441001505 | F8: "ФИЛИАЛ КОМПАНИИ С ОГРАНИЧЕННОЙ ОТВЕТСТВЕННОСТЬЮ БЕЙКЕР ХЬЮЗ СЕРВИСЕЗ ИНТЕРНЕШНЛ ЛЛСи (BAKER HUGHES SERVICES INTERNATIONAL LLC) В КАЗАХСТАНЕ". | G8: 23 | H8: ИНИС | I8: 40277 | J8: 40460 | L8: 46013 | O8: тематическая | R8: 44562 | S8: 45657 | T8: Байсалбаев М | U8: крупный | W8: роизводство продуктов нефтепереработки | X8: КГД МФ РК | AF8: РБ | AG8: 101110 | AH8: =AI8+AJ8 -> 1020721614 | AI8: 1020721614 | AJ8: 0 | AK8: 0 | AL8: 0 | AM8: =AN8+AO8+AP8+AQ8+AR8 -> 1020721614 | AN8: 1020721614 | AO8: 0 | AP8: 0 | AQ8: 0 | AR8: 0 | AS8: #N/A | AT8: да | AU8: 0 | AV8: правильно | AW8: правильно | AZ8: да | BD8: правильно
A9: =CONCATENATE(C9,"-",E9,"-",G9) -> 18xx-941040000097-180120250916TAC0006 | B9: 46071 | C9: 18xx | D9: ВКО | E9: 941040000097 | F9: АО "УМЗ" | G9: 180120250916TAC0006 | H9: ИСНА | I9: 180120250929OAP0001 | J9: 45916 | K9: 45924 | L9: 46002 | M9: 46006 | N9: тематическая | O9: Тематическая проверка | R9: 43831 | S9: 45291 | T9: Амирова Ж.К | U9: СКП | W9: Переработка ядерного топлива | X9: Приказ КГД МФ РК | Y9: 878 | Z9: 45912 | AD9: 357410759825 | AE9: 7.6 | AF9: РБ | AG9: 101110 | AH9: =AI9+AJ9 -> 983602729 | AI9: 983602729 | AJ9: 0 | AK9: 0 | AL9: 393441092 | AM9: =AN9+AO9+AP9+AQ9+AR9 -> 983602729 | AN9: 0 | AO9: 983602729 | AP9: 0 | AQ9: 0 | AR9: 0 | AS9: #N/A | AT9: нет | AU9: нет | AV9: правильно | AW9: правильно | AY9: да | BB9: да | BD9: правильно | BE9: мониторинг
A10: =CONCATENATE(C10,"-",E10,"-",G10) -> 03xx-20840001753-364 | B10: 46085 | C10: 03xx | D10: Акмолинская | E10: 20840001753 | F10: ГКП на ПХВ "Термо-Транзит" при отделе жилищно-коммунального хозяйства и жилищной инспекции Бурабайского района | G10: 364 | H10: ИНИС | I10: 364 | J10: 43712 | K10: 43719 | L10: 43839 | M10: 43840 | N10: тематическая | O10: #N/A | R10: 41640 | S10: 43465 | T10: Ертаев Е.А. | U10: микро | W10: Производство тепловой энергии самостоятельными котельными | X10: Решение государственного органа | AD10: 9269373333 | AE10: 0.8 | AF10: МБ | AG10: 101111 | AH10: =AI10+AJ10 -> 521587658 | AI10: 475920026 | AJ10: 45667632 | AK10: 0 | AL10: 111459660 | AM10: =AN10+AO10+AP10+AQ10+AR10 -> 924440127 | AN10: 410995906 | AO10: 0 | AP10: 401984561 | AQ10: 0 | AR10: 111459660 | AS10: #N/A | AT10: да | AU10: нет | AV10: норм | AW10: правильно | AX10: да | AZ10: да | BB10: да | BD10: правильно | BF10: 0 | BG10: #N/A | BH10: 0
A11: =CONCATENATE(C11,"-",E11,"-",G11) -> 21xx-81040006263-43 | B11: 46036 | C11: 21xx | D11: Жамбылская | E11: 81040006263 | F11: ТОО "Golden Compass Capital" | G11: 43 | H11: ИНИС | I11: 43 | J11: 45183 | K11: 45211 | L11: 45337 | M11: 45337 | O11: комплексная | R11: 43831 | S11: 44926 | T11: Косдаулетов К. | U11: Субъекты среднего предпринимательства | V11: нет | W11: Производство благородных (драгоценных) металлов | X11: Представление прокуратуры | Y11: 02-07-23-09120 | Z11: 45173 | AD11: 26529391912 | AE11: 0.8 | AF11: РБ | AG11: 101110 | AH11: =AI11+AJ11 -> 829029945 | AI11: 675597762 | AJ11: 153432183 | AK11: 1455198032 | AL11: 0 | AM11: =AN11+AO11+AP11+AQ11+AR11 -> 601870000 | AN11: 601870000 | AO11: 0 | AP11: 0 | AQ11: 0 | AR11: 0 | AS11: #N/A | AT11: да | AU11: 0 | AV11: правильно | AW11: правильно | AX11: да | BD11: правильно
A12: =CONCATENATE(C12,"-",E12,"-",G12) -> 60xx-970440003326-2302 | B12: 46078 | C12: 60xx | D12: г.Алматы | E12: 970440003326 | F12: АО Колеса | G12: 2302 | H12: ИНИС | I12: 2302 | J12: 45636 | K12: 45636 | L12: 46048 | O12: Тематическая | R12: 43466 | S12: 45291 | T12: Тынымбаев М.А. | U12: Крупное предпринимательство | X12: КГД МФ РК | AF12: РБ | AG12: 101110 | AH12: =AI12+AJ12 -> 12929864771 | AI12: 7834799272 | AJ12: 5095065499 | AK12: 0 | AL12: 0 | AM12: =AN12+AO12+AP12+AQ12+AR12 -> 405000000 | AN12: 405000000 | AO12: 0 | AP12: 0 | AQ12: 0 | AR12: 0 | AS12: УНА | AT12: да | AU12: да | AV12: 2026г. | AW12: правильно | AX12: да | BD12: правильно | BI12: 405000000
A13: =CONCATENATE(C13,"-",E13,"-",G13) -> 60xx-640004487-865 | B13: 46085 | C13: 60xx | D13: г.Алматы | E13: 640004487 | F13: ТОО "Мэри Кэй(Казахстан)" | G13: 865 | H13: ИНИС | I13: 865 | J13: 45160 | K13: 45160 | L13: 45260 | M13: 45261 | O13: тематическая | R13: 43101 | S13: 44926 | T13: Турешбаева Г.А. | U13: Крупное предпринимательство | W13: N47751 | X13: КГД МФ РК | AF13: РБ | AG13: 101110 | AH13: =AI13+AJ13 -> 2271513577 | AI13: 1370327728 | AJ13: 901185849 | AK13: 0 | AL13: 0 | AM13: =AN13+AO13+AP13+AQ13+AR13 -> 366120540 | AN13: 0 | AO13: 0 | AP13: 0 | AQ13: 0 | AR13: 366120540 | AS13: #N/A | AT13: да | AU13: нет | AV13: штраф | AW13: правильно | BB13: да | BD13: правильно
A14: =CONCATENATE(C14,"-",E14,"-",G14) -> 06xx-40540006757-120 | B14: 46050 | C14: 06xx | D14: Актюбинская | E14: 40540006757 | F14: ТОО "Актобе-Саулет" | G14: 120 | H14: ИНИС | I14: 120 | J14: 45810 | K14: 45818 | L14: 46048 | M14: 46048 | O14: Тематическая | R14: 44562 | S14: 45657 | T14: Жумашева Г. | U14: ССП | V14: - | W14: Строительство | X14: КГД МФ РК | Y14: - | Z14: - | AA14: - | AB14: - | AC14: - | AD14: 9147359571 | AE14: 7.05 | AF14: РБ | AG14: 105101 | AH14: =AI14+AJ14 -> 293606999 | AI14: 273931989 | AJ14: 19675010 | AK14: 0 | AL14: 0 | AM14: =AN14+AO14+AP14+AQ14+AR14 -> 293606999 | AN14: 96582043 | AO14: 177349946 | AP14: 19675010 | AQ14: 0 | AR14: 0 | AS14: УНА | AT14: да | AU14: да | AV14: 2026г. | AW14: правильно | AX14: да | AY14: да | AZ14: да | BD14: правильно | BI14: 423131
A15: =CONCATENATE(C15,"-",E15,"-",G15) -> 06xx-31040005996-060120250813TAC0002 | B15: 45713 | C15: 06xx | D15: Актюбинская | E15: 31040005996 | F15: ТОО "Актобе мунай маш комплект" | G15: 060120250813TAC0002 | H15: ИСНА | I15: 060120250813TAC0002 | J15: 45882 | K15: 45894 | L15: 46042 | M15: 46042 | N15: тематическая | O15: Тематическая проверка | R15: 44835 | S15: 45199 | T15: Жумашева Г. | U15: СКП | V15: - | W15: Строительство | X15: КГД МФ РК | Y15: 780 | Z15: 45880 | AA15: - | AB15: - | AC15: - | AD15: 46394970209 | AE15: 7.35 | AF15: РБ | AG15: 105101 | AH15: =AI15+AJ15 -> 223817148 | AI15: 146510138 | AJ15: 77307010 | AK15: 0 | AL15: 0 | AM15: =AN15+AO15+AP15+AQ15+AR15 -> 282421203 | AN15: 146510138 | AO15: 0 | AP15: 77307010 | AQ15: 0 | AR15: 58604055 | AS15: УНА | AT15: да | AU15: 0 | AV15: 2026г. | AW15: правильно | AX15: да | AZ15: да | BB15: да | BD15: правильно
